Workbook

Sheet Checks
B3: YoY CF : Blended ROI on financial assets are considered. Separate ROI and value of respective financial assets can be computed

Sheet List of TABs
B3: TABs
B4: 1a_Personal_Details
B5: 1b_Surplus & Net Worth
B6: 2_Income_Details
B7: 3_Expenses
B8: 4A_Mutual_Funds
B9: 4B_Equity_Stocks
B10: 4C_Fixed_Income
B11: 4D_Real_Estate
B12: 4E_Gold_Others
B13: 5_Monthly_Investments
B14: 6_Liquid_Capital
... B34: Risk Appetite of client to be done based on responses from clients on risk questannaire

Sheet Assumptions & Computation
B1: Assumptions
B2: Inflation
B3: General Inflation (Household) | D3: 0.07
B4: Educational Inflation | D4: 0.08
B5: Medical Inflation | D5: 0.09
B6: Wedding Inflation | D6: 0.08
B7: Personalised (Lifestyle) inflation | D7: 0.2 | E7: (Scooter to Sedan/SUV in 10 years - PV 1Lac, FV 15L, Time 10 Yrs) OR Basic Phone of Rs3K to Feature phone of Rs 50K
B8: Real Estate Inflation | D8: 0.08
B9: Vacation Inflation | D9: 0.08
B11: ROI | D11: Pre Tax | E11: Post Tax
B12: Income form Employment | D12: =8% | E12: =D12*0.7
B13: Income from business/profession | D13: 0.1 | E13: =D13*0.7
B14: Real Estate - Residential (Annual Income) | D14: 0.05 | E14: =D14*0.7
B15: Real Estate - Commercial (Annual Income) | D15: =5% | E15: =D15*0.75
B16: Gold (Annual Income) | D16: 0 | E16: 0
B17: Income from Others sources / non financial assets | D17: 0.05 | E17: =D17*0.7
B19: ROI | D19: Pre Tax | E19: Post Tax
B20: Own Business/Professsion | D20: 0.25 | E20: =D20*(1-0.25-0.05)
B21: Equity - / MF Aggressive (Small/Mid Cap) | D21: 0.14 | E21: =D21*(1-0.125)
B22: Equity / MF - Hybrid (Large and Mid Cap) | D22: 0.12 | E22: =D22*(1-0.125)
B23: Equity / MF - Conservative (Large Cap) | D23: 0.1 | E23: =D23*(1-0.125)
B24: Bank FDs/RD | D24: 0.065 | E24: =D24*(1-0.3)
B25: Bonds/Debt/Debentures | D25: 0.075 | E25: =D25*(1-0.3)
B26: PPF etc | D26: 0.071 | E26: =D26*(1-0)
B27: EPFcetc | D27: 0.081 | E27: =D27*(1-0)
B28: Sukanya/Sr Citizen | D28: 0.081 | E28: =D28*(1-0)
B29: SGB | D29: =2.5%+5% | E29: =5%+2.5%*0.7 | F29: Tax free if held for 8 years
B30: ULIP/Endownment Plans | D30: 0.06 | E30: =D30
B31: NPS | D31: 0.07 | E31: =D31
B32: Liquid Fund | D32: 0.055 | E32: =D32*(1-0.3)
B33: Savings Bank Interest | D33: 0.035 | E33: =D33*(1-0.3)
B34: Real Estate - Residential (Appreciation) | D34: 0.08 | E34: =D34*(1-0.125)
B35: Real Estate - Commercial (Appreciation) | D35: 0.08 | E35: =D35*(1-0.125)
B36: Gold (Appreciation) | D36: 0.08 | E36: =D36*(1-0.125)
B37: Crypto
B38: Others (Pls specifiy)
B39: Others (Pls specifiy)
B40: Blended (Equal Weight) ROI | D40: =AVERAGE(D20:D39) | E40: =AVERAGE(E20:E39)
B42: Retirement Planning
B43: Life Expectancy of Mr M | C43: Input | D43: Years | E43: 75
...

Sheet YoY Cash Flow
B2: Summary of Income & Expenditure | O2: Computing financial assets at the end of each year | X2: Computing non - financial assets at the end of each year | AC2: Networth
B4: Year | C4: Year | D4: Age of Primary Client | E4: Income form Employment | F4: Income from business/profession | G4: Rental Income | H4: Income from Others sources / non financial assets | I4: Total Income | J4: Regular Expenses (Except Loans and Major One Time) | K4: Loan Repayments | L4: Total Outflow | M4: Surplus | N4: x | O4: Year | P4: Opening Balance of Finanical Assets | Q4: Net Annual Cash Savings (Family) | R4: Major Withdrawls | S4: Income from investments | T4: Lumpsum Further deposit / (Withdrawl) | U4: Remarks | V4: Closing Balance of Financial Assets | W4: x | X4: Opening Balance of Non Finanical Assets (Mostly Real Estate / Gold) | Y4: Addition / (Disposal) of Fixed Assets | Z4: Appreciation/(Depreciation) | AA4: Closing Balance of Non Finanical Assets | AB4: x | AC4: Total Networth | AD4: Total Networth INR Crore
B5: Increase YoY (Net of Taxes) % | E5: ='Assumptions & Computation'!E12 | F5: ='Assumptions & Computation'!E13 | G5: ='Assumptions & Computation'!E14 | H5: ='Assumptions & Computation'!E17 | J5: ='Assumptions & Computation'!D3 | K5: Actual | P5: Real Estate (Not considered for earnings or increase in valuation) | S5: ='11. Inc Exp,Networth,Rec Invest'!K42 | Z5: ='11. Inc Exp,Networth,Rec Invest'!K47
B6: Y0 | C6: 2026 | D6: ='1_Personal_Details'!D5 | E6: ='2_Income'!I24*12 | F6: ='2_Income'!I25*12 | G6: ='2_Income'!I26*12 | H6: =SUM('2_Income'!I27:I28) | I6: =SUM(E6:H6) | J6: =('3_Expenses '!I26-SUM('3_Expenses '!I23:I25))*12 | K6: =SUM('3_Expenses '!I23:I25)*12 | L6: =SUM(J6:K6) | M6: =I6-L6 | O6: =C6 | P6: ='11. Inc Exp,Networth,Rec Invest'!I42 | Q6: =M6 | R6: =-SUMIF('10_Financial_Goals'!$C$3:$C$12,'YoY Cash Flow'!C6,'10_Financial_Goals'!$H$3:$H$9) | S6: =(P6+Q6/2-R6)*(S$5) | V6: =P6+Q6+R6+S6+T6 | X6: ='11. Inc Exp,Networth,Rec Invest'!I47 | Z6: =X6*Z$5 | AA6: =SUM(X6:Z6) | AC6: =SUM(V6,AA6) | AD6: =AC6/10^7
B7: Y1 | C7: =C6+1 | D7: =D6+1 | E7: =E6*(1+E$5) | F7: =F6*(1+F$5) | G7: =G6*(1+G$5) | I7: =SUM(E7:H7) | J7: =J6*(1+J$5) | K7: =K6 | L7: =SUM(J7:K7) | M7: =I7-L7 | O7: =O6+1 | P7: =V6 | Q7: =M7 | R7: =-SUMIF('10_Financial_Goals'!$C$3:$C$12,'YoY Cash Flow'!C7,'10_Financial_Goals'!$H$3:$H$9) | S7: =(P7+Q7/2-R7)*(S$5) | V7: =P7+Q7+R7+S7+T7 | X7: =AA6 | Z7: =X7*Z$5 | AA7: =SUM(X7:Z7) | AC7: =SUM(V7,AA7) | AD7: =AC7/10^7
B8: Y2 | C8: =C7+1 | D8: =D7+1 | E8: =E7*(1+E$5) | F8: =F7*(1+F$5) | G8: =G7*(1+G$5) | I8: =SUM(E8:H8) | J8: =J7*(1+J$5) | K8: =K7 | L8: =SUM(J8:K8) | M8: =I8-L8 | O8: =O7+1 | P8: =V7 | Q8: =M8 | R8: =-SUMIF('10_Financial_Goals'!$C$3:$C$12,'YoY Cash Flow'!C8,'10_Financial_Goals'!$H$3:$H$9) | S8: =(P8+Q8/2-R8)*(S$5) | V8: =P8+Q8+R8+S8+T8 | X8: =AA7 | Z8: =X8*Z$5 | AA8: =SUM(X8:Z8) | AC8: =SUM(V8,AA8) | AD8: =AC8/10^7
B9: Y3 | C9: =C8+1 | D9: =D8+1 | E9: =E8*(1+E$5) | F9: =F8*(1+F$5) | G9: =G8*(1+G$5) | I9: =SUM(E9:H9) | J9: =J8*(1+J$5) | K9: =K8 | L9: =SUM(J9:K9) | M9: =I9-L9 | O9: =O8+1 | P9: =V8 | Q9: =M9 | R9: =-SUMIF('10_Financial_Goals'!$C$3:$C$12,'YoY Cash Flow'!C9,'10_Financial_Goals'!$H$3:$H$9) | S9: =(P9+Q9/2-R9)*(S$5) | T9: 200000 | U9: Bonus Expected | V9: =P9+Q9+R9+S9+T9 | X9: =AA8 | Z9: =X9*Z$5 | AA9: =SUM(X9:Z9) | AC9: =SUM(V9,AA9) | AD9: =AC9/10^7
B10: Y4 | C10: =C9+1 | D10: =D9+1 | E10: =E9*(1+E$5) | F10: =F9*(1+F$5) | G10: =G9*(1+G$5) | I10: =SUM(E10:H10) | J10: =J9*(1+J$5) | K10: =K9 | L10: =SUM(J10:K10) | M10: =I10-L10 | O10: =O9+1 | P10: =V9 | Q10: =M10 | R10: =-SUMIF('10_Financial_Goals'!$C$3:$C$12,'YoY Cash Flow'!C10,'10_Financial_Goals'!$H$3:$H$9) | S10: =(P10+Q10/2-R10)*(S$5) | V10: =P10+Q10+R10+S10+T10 | X10: =AA9 | Z10: =X10*Z$5 | AA10: =SUM(X10:Z10) | AC10: =SUM(V10,AA10) | AD10: =AC10/10^7
B11: Y5 | C11: =C10+1 | D11: =D10+1 | E11: =E10*(1+E$5) | F11: =F10*(1+F$5) | G11: =G10*(1+G$5) | I11: =SUM(E11:H11) | J11: =J10*(1+J$5) | K11: =K10 | L11: =SUM(J11:K11) | M11: =I11-L11 | O11: =O10+1 | P11: =V10 | Q11: =M11 | R11: =-SUMIF('10_Financial_Goals'!$C$3:$C$12,'YoY Cash Flow'!C11,'10_Financial_Goals'!$H$3:$H$9) | S11: =(P11+Q11/2-R11)*(S$5) | V11: =P11+Q11+R11+S11+T11 | X11: =AA10 | Z11: =X11*Z$5 | AA11: =SUM(X11:Z11) | AC11: =SUM(V11,AA11) | AD11: =AC11/10^7
B12: Y6 | C12: =C11+1 | D12: =D11+1 | E12: =E11*(1+E$5) | F12: =F11*(1+F$5) | G12: =G11*(1+G$5) | I12: =SUM(E12:H12) | J12: =J11*(1+J$5) | K12: =K11 | L12: =SUM(J12:K12) | M12: =I12-L12 | O12: =O11+1 | P12: =V11 | Q12: =M12 | R12: =-SUMIF('10_Financial_Goals'!$C$3:$C$12,'YoY Cash Flow'!C12,'10_Financial_Goals'!$H$3:$H$9) | S12: =(P12+Q12/2-R12)*(S$5) | V12: =P12+Q12+R12+S12+T12 | X12: =AA11 | Z12: =X12*Z$5 | AA12: =SUM(X12:Z12) | AC12: =SUM(V12,AA12) | AD12: =AC12/10^7
B13: Y7 | C13: =C12+1 | D13: =D12+1 | E13: =E12*(1+E$5) | F13: =F12*(1+F$5) | G13: =G12*(1+G$5) | I13: =SUM(E13:H13) | J13: =J12*(1+J$5) | K13: =K12 | L13: =SUM(J13:K13) | M13: =I13-L13 | O13: =O12+1 | P13: =V12 | Q13: =M13 | R13: =-SUMIF('10_Financial_Goals'!$C$3:$C$12,'YoY Cash Flow'!C13,'10_Financial_Goals'!$H$3:$H$9) | S13: =(P13+Q13/2-R13)*(S$5) | V13: =P13+Q13+R13+S13+T13 | X13: =AA12 | Z13: =X13*Z$5 | AA13: =SUM(X13:Z13) | AC13: =SUM(V13,AA13) | AD13: =AC13/10^7
B14: Y8 | C14: =C13+1 | D14: =D13+1 | E14: =E13*(1+E$5) | F14: =F13*(1+F$5) | G14: =G13*(1+G$5) | I14: =SUM(E14:H14) | J14: =J13*(1+J$5) | K14: =K13 | L14: =SUM(J14:K14) | M14: =I14-L14 | O14: =O13+1 | P14: =V13 | Q14: =M14 | R14: =-SUMIF('10_Financial_Goals'!$C$3:$C$12,'YoY Cash Flow'!C14,'10_Financial_Goals'!$H$3:$H$9) | S14: =(P14+Q14/2-R14)*(S$5) | V14: =P14+Q14+R14+S14+T14 | X14: =AA13 | Z14: =X14*Z$5 | AA14: =SUM(X14:Z14) | AC14: =SUM(V14,AA14) | AD14: =AC14/10^7
B15: Y9 | C15: =C14+1 | D15: =D14+1 | E15: =E14*(1+E$5) | F15: =F14*(1+F$5) | G15: =G14*(1+G$5) | I15: =SUM(E15:H15) | J15: =J14*(1+J$5) | K15: =K14 | L15: =SUM(J15:K15) | M15: =I15-L15 | O15: =O14+1 | P15: =V14 | Q15: =M15 | R15: =-SUMIF('10_Financial_Goals'!$C$3:$C$12,'YoY Cash Flow'!C15,'10_Financial_Goals'!$H$3:$H$9) | S15: =(P15+Q15/2-R15)*(S$5) | V15: =P15+Q15+R15+S15+T15 | X15: =AA14 | Z15: =X15*Z$5 | AA15: =SUM(X15:Z15) | AC15: =SUM(V15,AA15) | AD15: =AC15/10^7
B16: Y10 | C16: =C15+1 | D16: =D15+1 | E16: =E15*(1+E$5) | F16: =F15*(1+F$5) | G16: =G15*(1+G$5) | I16: =SUM(E16:H16) | J16: =J15*(1+J$5) | L16: =SUM(J16:K16) | M16: =I16-L16 | O16: =O15+1 | P16: =V15 | Q16: =M16 | R16: =-SUMIF('10_Financial_Goals'!$C$3:$C$12,'YoY Cash Flow'!C16,'10_Financial_Goals'!$H$3:$H$9) | S16: =(P16+Q16/2-R16)*(S$5) | V16: =P16+Q16+R16+S16+T16 | X16: =AA15 | Z16: =X16*Z$5 | AA16: =SUM(X16:Z16) | AC16: =SUM(V16,AA16) | AD16: =AC16/10^7
B17: Y11 | C17: =C16+1 | D17: =D16+1 | E17: =E16*(1+E$5) | F17: =F16*(1+F$5) | G17: =G16*(1+G$5) | I17: =SUM(E17:H17) | J17: =J16*(1+J$5) | L17: =SUM(J17:K17) | M17: =I17-L17 | O17: =O16+1 | P17: =V16 | Q17: =M17 | R17: =-SUMIF('10_Financial_Goals'!$C$3:$C$12,'YoY Cash Flow'!C17,'10_Financial_Goals'!$H$3:$H$9) | S17: =(P17+Q17/2-R17)*(S$5) | T17: -500000 | U17: Knee Surgery planned for parents who don’t have insurance | V17: =P17+Q17+R17+S17+T17 | X17: =AA16 | Z17: =X17*Z$5 | AA17: =SUM(X17:Z17) | AC17: =SUM(V17,AA17) | AD17: =AC17/10^7
B18: Y12 | C18: =C17+1 | D18: =D17+1 | E18: =E17*(1+E$5) | F18: =F17*(1+F$5) | G18: =G17*(1+G$5) | I18: =SUM(E18:H18) | J18: =J17*(1+J$5) | L18: =SUM(J18:K18) | M18: =I18-L18 | O18: =O17+1 | P18: =V17 | Q18: =M18 | R18: =-SUMIF('10_Financial_Goals'!$C$3:$C$12,'YoY Cash Flow'!C18,'10_Financial_Goals'!$H$3:$H$9) | S18: =(P18+Q18/2-R18)*(S$5) | V18: =P18+Q18+R18+S18+T18 | X18: =AA17 | Z18: =X18*Z$5 | AA18: =SUM(X18:Z18) | AC18: =SUM(V18,AA18) | AD18: =AC18/10^7
B19: Y13 | C19: =C18+1 | D19: =D18+1 | E19: =E18*(1+E$5) | F19: =F18*(1+F$5) | G19: =G18*(1+G$5) | I19: =SUM(E19:H19) | J19: =J18*(1+J$5) | L19: =SUM(J19:K19) | M19: =I19-L19 | O19: =O18+1 | P19: =V18 | Q19: =M19 | R19: =-SUMIF('10_Financial_Goals'!$C$3:$C$12,'YoY Cash Flow'!C19,'10_Financial_Goals'!$H$3:$H$9) | S19: =(P19+Q19/2-R19)*(S$5) | V19: =P19+Q19+R19+S19+T19 | X19: =AA18 | Z19: =X19*Z$5 | AA19: =SUM(X19:Z19) | AC19: =SUM(V19,AA19) | AD19: =AC19/10^7
B20: Y14 | C20: =C19+1 | D20: =D19+1 | E20: =E19*(1+E$5) | F20: =F19*(1+F$5) | G20: =G19*(1+G$5) | I20: =SUM(E20:H20) | J20: =J19*(1+J$5) | L20: =SUM(J20:K20) | M20: =I20-L20 | O20: =O19+1 | P20: =V19 | Q20: =M20 | R20: =-SUMIF('10_Financial_Goals'!$C$3:$C$12,'YoY Cash Flow'!C20,'10_Financial_Goals'!$H$3:$H$9) | S20: =(P20+Q20/2-R20)*(S$5) | V20: =P20+Q20+R20+S20+T20 | X20: =AA19 | Z20: =X20*Z$5 | AA20: =SUM(X20:Z20) | AC20: =SUM(V20,AA20) | AD20: =AC20/10^7
B21: Y15 | C21: =C20+1 | D21: =D20+1 | E21: =E20*(1+E$5) | F21: =F20*(1+F$5) | G21: =G20*(1+G$5) | I21: =SUM(E21:H21) | J21: =J20*(1+J$5) | L21: =SUM(J21:K21) | M21: =I21-L21 | O21: =O20+1 | P21: =V20 | Q21: =M21 | R21: =-SUMIF('10_Financial_Goals'!$C$3:$C$12,'YoY Cash Flow'!C21,'10_Financial_Goals'!$H$3:$H$9) | S21: =(P21+Q21/2-R21)*(S$5) | V21: =P21+Q21+R21+S21+T21 | X21: =AA20 | Z21: =X21*Z$5 | AA21: =SUM(X21:Z21) | AC21: =SUM(V21,AA21) | AD21: =AC21/10^7
B22: Y16 | C22: =C21+1 | D22: =D21+1 | E22: =E21*(1+E$5) | F22: =F21*(1+F$5) | G22: =G21*(1+G$5) | I22: =SUM(E22:H22) | J22: =J21*(1+J$5) | L22: =SUM(J22:K22) | M22: =I22-L22 | O22: =O21+1 | P22: =V21 | Q22: =M22 | R22: =-SUMIF('10_Financial_Goals'!$C$3:$C$12,'YoY Cash Flow'!C22,'10_Financial_Goals'!$H$3:$H$9) | S22: =(P22+Q22/2-R22)*(S$5) | V22: =P22+Q22+R22+S22+T22 | X22: =AA21 | Z22: =X22*Z$5 | AA22: =SUM(X22:Z22) | AC22: =SUM(V22,AA22) | AD22: =AC22/10^7
B23: Y17 | C23: =C22+1 | D23: =D22+1 | E23: =E22*(1+E$5) | F23: =F22*(1+F$5) | G23: =G22*(1+G$5) | I23: =SUM(E23:H23) | J23: =J22*(1+J$5) | L23: =SUM(J23:K23) | M23: =I23-L23 | O23: =O22+1 | P23: =V22 | Q23: =M23 | R23: =-SUMIF('10_Financial_Goals'!$C$3:$C$12,'YoY Cash Flow'!C23,'10_Financial_Goals'!$H$3:$H$9) | S23: =(P23+Q23/2-R23)*(S$5) | V23: =P23+Q23+R23+S23+T23 | X23: =AA22 | Z23: =X23*Z$5 | AA23: =SUM(X23:Z23) | AC23: =SUM(V23,AA23) | AD23: =AC23/10^7
B24: Y18 | C24: =C23+1 | D24: =D23+1 | E24: =E23*(1+E$5) | F24: =F23*(1+F$5) | G24: =G23*(1+G$5) | I24: =SUM(E24:H24) | J24: =J23*(1+J$5) | L24: =SUM(J24:K24) | M24: =I24-L24 | O24: =O23+1 | P24: =V23 | Q24: =M24 | R24: =-SUMIF('10_Financial_Goals'!$C$3:$C$12,'YoY Cash Flow'!C24,'10_Financial_Goals'!$H$3:$H$9) | S24: =(P24+Q24/2-R24)*(S$5) | V24: =P24+Q24+R24+S24+T24 | X24: =AA23 | Z24: =X24*Z$5 | AA24: =SUM(X24:Z24) | AC24: =SUM(V24,AA24) | AD24: =AC24/10^7
B25: Y19 | C25: =C24+1 | D25: =D24+1 | E25: =E24*(1+E$5) | F25: =F24*(1+F$5) | G25: =G24*(1+G$5) | H25: =Y25*4% | I25: =SUM(E25:H25) | J25: =J24*(1+J$5) | L25: =SUM(J25:K25) | M25: =I25-L25 | O25: =O24+1 | P25: =V24 | Q25: =M25 | R25: =-SUMIF('10_Financial_Goals'!$C$3:$C$12,'YoY Cash Flow'!C25,'10_Financial_Goals'!$H$3:$H$9) | S25: =(P25+Q25/2-R25)*(S$5) | V25: =P25+Q25+R25+S25+T25 | X25: =AA24 | Z25: =X25*Z$5 | AA25: =SUM(X25:Z25) | AC25: =SUM(V25,AA25) | AD25: =AC25/10^7
A26: Retirement Age | B26: Y20 | C26: =C25+1 | D26: =D25+1 | E26: =E25*(1+E$5) | F26: =F25*(1+F$5) | G26: =G25*(1+G$5) | H26: =H25*(1+H$5) | I26: =SUM(E26:H26) | J26: =J25*(1+J$5) | L26: =SUM(J26:K26) | M26: =I26-L26 | O26: =O25+1 | P26: =V25 | Q26: =M26 | R26: =-SUMIF('10_Financial_Goals'!$C$3:$C$12,'YoY Cash Flow'!C26,'10_Financial_Goals'!$H$3:$H$9) | S26: =(P26+Q26/2-R26)*(S$5) | V26: =P26+Q26+R26+S26+T26 | X26: =AA25 | Z26: =X26*Z$5 | AA26: =SUM(X26:Z26) | AC26: =SUM(V26,AA26) | AD26: =AC26/10^7
B27: Y21 | C27: =C26+1 | D27: =D26+1 | F27: =F26*(1+F$5) | G27: =G26*(1+G$5) | H27: =H26*(1+H$5) | I27: =SUM(E27:H27) | J27: =J26*(1+J$5) | L27: =SUM(J27:K27) | M27: =I27-L27 | O27: =O26+1 | P27: =V26 | Q27: =M27 | R27: =-SUMIF('10_Financial_Goals'!$C$3:$C$12,'YoY Cash Flow'!C27,'10_Financial_Goals'!$H$3:$H$9) | S27: =(P27+Q27/2-R27)*(S$5) | V27: =P27+Q27+R27+S27+T27 | X27: =AA26 | Z27: =X27*Z$5 | AA27: =SUM(X27:Z27) | AC27: =SUM(V27,AA27) | AD27: =AC27/10^7
B28: Y22 | C28: =C27+1 | D28: =D27+1 | F28: =F27*(1+F$5) | G28: =G27*(1+G$5) | H28: =H27*(1+H$5) | I28: =SUM(E28:H28) | J28: =J27*(1+J$5) | L28: =SUM(J28:K28) | M28: =I28-L28 | O28: =O27+1 | P28: =V27 | Q28: =M28 | R28: =-SUMIF('10_Financial_Goals'!$C$3:$C$12,'YoY Cash Flow'!C28,'10_Financial_Goals'!$H$3:$H$9) | S28: =(P28+Q28/2-R28)*(S$5) | V28: =P28+Q28+R28+S28+T28 | X28: =AA27 | Z28: =X28*Z$5 | AA28: =SUM(X28:Z28) | AC28: =SUM(V28,AA28) | AD28: =AC28/10^7
B29: Y23 | C29: =C28+1 | D29: =D28+1 | F29: =F28*(1+F$5) | G29: =G28*(1+G$5) | H29: =H28*(1+H$5) | I29: =SUM(E29:H29) | J29: =J28*(1+J$5) | L29: =SUM(J29:K29) | M29: =I29-L29 | O29: =O28+1 | P29: =V28 | Q29: =M29 | R29: =-SUMIF('10_Financial_Goals'!$C$3:$C$12,'YoY Cash Flow'!C29,'10_Financial_Goals'!$H$3:$H$9) | S29: =(P29+Q29/2-R29)*(S$5) | V29: =P29+Q29+R29+S29+T29 | X29: =AA28 | Z29: =X29*Z$5 | AA29: =SUM(X29:Z29) | AC29: =SUM(V29,AA29) | AD29: =AC29/10^7
A30: Business Income Ceases | B30: Y24 | C30: =C29+1 | D30: =D29+1 | F30: =F29*(1+F$5) | G30: =G29*(1+G$5) | H30: =H29*(1+H$5) | I30: =SUM(E30:H30) | J30: =J29*(1+J$5) | L30: =SUM(J30:K30) | M30: =I30-L30 | O30: =O29+1 | P30: =V29 | Q30: =M30 | R30: =-SUMIF('10_Financial_Goals'!$C$3:$C$12,'YoY Cash Flow'!C30,'10_Financial_Goals'!$H$3:$H$9) | S30: =(P30+Q30/2-R30)*(S$5) | T30: 10000000 | U30: Reverse Mortgage | V30: =P30+Q30+R30+S30+T30 | X30: =AA29 | Z30: =X30*Z$5 | AA30: =SUM(X30:Z30) | AC30: =SUM(V30,AA30) | AD30: =AC30/10^7
B31: Y25 | C31: =C30+1 | D31: =D30+1 | G31: =G30*(1+G$5) | H31: =H30*(1+H$5) | I31: =SUM(E31:H31) | J31: =J30*(1+J$5) | L31: =SUM(J31:K31) | M31: =I31-L31 | O31: =O30+1 | P31: =V30 | Q31: =M31 | R31: =-SUMIF('10_Financial_Goals'!$C$3:$C$12,'YoY Cash Flow'!C31,'10_Financial_Goals'!$H$3:$H$9) | S31: =(P31+Q31/2-R31)*(S$5) | V31: =P31+Q31+R31+S31+T31 | X31: =AA30 | Z31: =X31*Z$5 | AA31: =SUM(X31:Z31) | AC31: =SUM(V31,AA31) | AD31: =AC31/10^7
B32: Y26 | C32: =C31+1 | D32: =D31+1 | G32: =G31*(1+G$5) | H32: =H31*(1+H$5) | I32: =SUM(E32:H32) | J32: =J31*(1+J$5) | L32: =SUM(J32:K32) | M32: =I32-L32 | O32: =O31+1 | P32: =V31 | Q32: =M32 | R32: =-SUMIF('10_Financial_Goals'!$C$3:$C$12,'YoY Cash Flow'!C32,'10_Financial_Goals'!$H$3:$H$9) | S32: =(P32+Q32/2-R32)*(S$5) | T32: 10000000 | U32: Reverse Mortgage | V32: =P32+Q32+R32+S32+T32 | X32: =AA31 | Z32: =X32*Z$5 | AA32: =SUM(X32:Z32) | AC32: =SUM(V32,AA32) | AD32: =AC32/10^7
B33: Y27 | C33: =C32+1 | D33: =D32+1 | G33: =G32*(1+G$5) | H33: =H32*(1+H$5) | I33: =SUM(E33:H33) | J33: =J32*(1+J$5) | L33: =SUM(J33:K33) | M33: =I33-L33 | O33: =O32+1 | P33: =V32 | Q33: =M33 | R33: =-SUMIF('10_Financial_Goals'!$C$3:$C$12,'YoY Cash Flow'!C33,'10_Financial_Goals'!$H$3:$H$9) | S33: =(P33+Q33/2-R33)*(S$5) | V33: =P33+Q33+R33+S33+T33 | X33: =AA32 | Z33: =X33*Z$5 | AA33: =SUM(X33:Z33) | AC33: =SUM(V33,AA33) | AD33: =AC33/10^7
B34: Y28 | C34: =C33+1 | D34: =D33+1 | G34: =G33*(1+G$5) | H34: =H33*(1+H$5) | I34: =SUM(E34:H34) | J34: =J33*(1+J$5) | L34: =SUM(J34:K34) | M34: =I34-L34 | O34: =O33+1 | P34: =V33 | Q34: =M34 | R34: =-SUMIF('10_Financial_Goals'!$C$3:$C$12,'YoY Cash Flow'!C34,'10_Financial_Goals'!$H$3:$H$9) | S34: =(P34+Q34/2-R34)*(S$5) | T34: 10000000 | U34: Reverse Mortgage | V34: =P34+Q34+R34+S34+T34 | X34: =AA33 | Z34: =X34*Z$5 | AA34: =SUM(X34:Z34) | AC34: =SUM(V34,AA34) | AD34: =AC34/10^7
B35: Y29 | C35: =C34+1 | D35: =D34+1 | G35: =G34*(1+G$5) | H35: =H34*(1+H$5) | I35: =SUM(E35:H35) | J35: =J34*(1+J$5) | L35: =SUM(J35:K35) | M35: =I35-L35 | O35: =O34+1 | P35: =V34 | Q35: =M35 | R35: =-SUMIF('10_Financial_Goals'!$C$3:$C$12,'YoY Cash Flow'!C35,'10_Financial_Goals'!$H$3:$H$9) | S35: =(P35+Q35/2-R35)*(S$5) | V35: =P35+Q35+R35+S35+T35 | X35: =AA34 | Z35: =X35*Z$5 | AA35: =SUM(X35:Z35) | AC35: =SUM(V35,AA35) | AD35: =AC35/10^7
B36: Y30 | C36: =C35+1 | D36: =D35+1 | G36: =G35*(1+G$5) | H36: =H35*(1+H$5) | I36: =SUM(E36:H36) | J36: =J35*(1+J$5) | L36: =SUM(J36:K36) | M36: =I36-L36 | O36: =O35+1 | P36: =V35 | Q36: =M36 | R36: =-SUMIF('10_Financial_Goals'!$C$3:$C$12,'YoY Cash Flow'!C36,'10_Financial_Goals'!$H$3:$H$9) | S36: =(P36+Q36/2-R36)*(S$5) | T36: 10000000 | U36: Reverse Mortgage | V36: =P36+Q36+R36+S36+T36 | X36: =AA35 | Z36: =X36*Z$5 | AA36: =SUM(X36:Z36) | AC36: =SUM(V36,AA36) | AD36: =AC36/10^7
B37: Y31 | C37: =C36+1 | D37: =D36+1 | G37: =G36*(1+G$5) | H37: =H36*(1+H$5) | I37: =SUM(E37:H37) | J37: =J36*(1+J$5) | L37: =SUM(J37:K37) | M37: =I37-L37 | O37: =O36+1 | P37: =V36 | Q37: =M37 | R37: =-SUMIF('10_Financial_Goals'!$C$3:$C$12,'YoY Cash Flow'!C37,'10_Financial_Goals'!$H$3:$H$9) | S37: =(P37+Q37/2-R37)*(S$5) | V37: =P37+Q37+R37+S37+T37 | X37: =AA36 | Z37: =X37*Z$5 | AA37: =SUM(X37:Z37) | AC37: =SUM(V37,AA37) | AD37: =AC37/10^7
B38: Y32 | C38: =C37+1 | D38: =D37+1 | G38: =G37*(1+G$5) | H38: =H37*(1+H$5) | I38: =SUM(E38:H38) | J38: =J37*(1+J$5) | L38: =SUM(J38:K38) | M38: =I38-L38 | O38: =O37+1 | P38: =V37 | Q38: =M38 | R38: =-SUMIF('10_Financial_Goals'!$C$3:$C$12,'YoY Cash Flow'!C38,'10_Financial_Goals'!$H$3:$H$9) | S38: =(P38+Q38/2-R38)*(S$5) | T38: 10000000 | U38: Reverse Mortgage | V38: =P38+Q38+R38+S38+T38 | X38: =AA37 | Z38: =X38*Z$5 | AA38: =SUM(X38:Z38) | AC38: =SUM(V38,AA38) | AD38: =AC38/10^7
B39: Y33 | C39: =C38+1 | D39: =D38+1 | G39: =G38*(1+G$5) | H39: =H38*(1+H$5) | I39: =SUM(E39:H39) | J39: =J38*(1+J$5) | L39: =SUM(J39:K39) | M39: =I39-L39 | O39: =O38+1 | P39: =V38 | Q39: =M39 | R39: =-SUMIF('10_Financial_Goals'!$C$3:$C$12,'YoY Cash Flow'!C39,'10_Financial_Goals'!$H$3:$H$9) | S39: =(P39+Q39/2-R39)*(S$5) | V39: =P39+Q39+R39+S39+T39 | X39: =AA38 | Z39: =X39*Z$5 | AA39: =SUM(X39:Z39) | AC39: =SUM(V39,AA39) | AD39: =AC39/10^7
B40: Y34 | C40: =C39+1 | D40: =D39+1 | G40: =G39*(1+G$5) | H40: =H39*(1+H$5) | I40: =SUM(E40:H40) | J40: =J39*(1+J$5) | L40: =SUM(J40:K40) | M40: =I40-L40 | O40: =O39+1 | P40: =V39 | Q40: =M40 | R40: =-SUMIF('10_Financial_Goals'!$C$3:$C$12,'YoY Cash Flow'!C40,'10_Financial_Goals'!$H$3:$H$9) | S40: =(P40+Q40/2-R40)*(S$5) | V40: =P40+Q40+R40+S40+T40 | X40: =AA39 | Z40: =X40*Z$5 | AA40: =SUM(X40:Z40) | AC40: =SUM(V40,AA40) | AD40: =AC40/10^7
B41: Y35 | C41: =C40+1 | D41: =D40+1 | G41: =G40*(1+G$5) | H41: =H40*(1+H$5) | I41: =SUM(E41:H41) | J41: =J40*(1+J$5) | L41: =SUM(J41:K41) | M41: =I41-L41 | O41: =O40+1 | P41: =V40 | Q41: =M41 | R41: =-SUMIF('10_Financial_Goals'!$C$3:$C$12,'YoY Cash Flow'!C41,'10_Financial_Goals'!$H$3:$H$9) | S41: =(P41+Q41/2-R41)*(S$5) | V41: =P41+Q41+R41+S41+T41 | X41: =AA40 | Z41: =X41*Z$5 | AA41: =SUM(X41:Z41) | AC41: =SUM(V41,AA41) | AD41: =AC41/10^7
B42: Y36 | C42: =C41+1 | D42: =D41+1 | G42: =G41*(1+G$5) | H42: =H41*(1+H$5) | I42: =SUM(E42:H42) | J42: =J41*(1+J$5) | L42: =SUM(J42:K42) | M42: =I42-L42 | O42: =O41+1 | P42: =V41 | Q42: =M42 | R42: =-SUMIF('10_Financial_Goals'!$C$3:$C$12,'YoY Cash Flow'!C42,'10_Financial_Goals'!$H$3:$H$9) | S42: =(P42+Q42/2-R42)*(S$5) | V42: =P42+Q42+R42+S42+T42 | X42: =AA41 | Z42: =X42*Z$5 | AA42: =SUM(X42:Z42) | AC42: =SUM(V42,AA42) | AD42: =AC42/10^7
...

Sheet Debt Mgt
B2: Debt is not always bad.
B3: We should differentiating loan taken for investments (Real Estate/Stocks etc) vs Consumption .
B4: If the IRR of returns from investments done by taking debt is higher than rate of interest debt can prove beneficial
B5: However debt repayment should nit become burdensome . i.e DSCR should be >1.5
B8: Typical Ratios to evaluate adequacy of debt : | R8: DSCR = Income Avaibale for debt servicing / EMI :
B9: •debt servicing ratio (DSCR) | E9: If DSCR is <1.25 , reduce debt | R9: Net Income | S9: ='2_Income'!I30
B10: •debt to income ratio (DTI) | R10: Expenses without EMI | S10: ='3_Expenses '!I26-'3_Expenses '!I23-'3_Expenses '!I24
B11: •debt to net worth ratio (DNI) | R11: Income Availabe for debt service | S11: =S9-S10
B13: Strategies to reduce debt faster | R13: EMI | S13: ='3_Expenses '!I23
B14: Avalanche (High rate loans first) | E14: Suggest people reduce high interest bearing first like credit card debt followed by personal loan etc | R14: DSCR | S14: =S11/S13
B15: Snowball (Small loans first)
B16: Blizzard (First Snowball, then Alavanche)
B18: Typical repayment sequence (Based on post tax cost of borrowing') :
B19: Unsecured | C19: Credit card debt
D20: Private Loans/ P2P Loans( Loans from friends and family)
D21: Personal loan
B22: Secured | D22: Loan against securities, gold, property etc
D23: Business Loan / Cash Credit
D24: Vehicle loan
D25: Education Loan
D26: Home Loan

Sheet Tax Planning
B2: Instrument | C2: Tax rate | D2: Holding period | E2: Exemption / deduction | F2: Old regime | G2: New regime
B3: Equity & equity MFs | C3: STCG 20% | D3: STCG <12 months | E3: ₹1.25L/yr LTCG free | F3: ₹1.25L exemption | G3: ₹1.25L exemption
C4: LTCG 12.5%LTCG >₹1.25L taxable | D4: LTCG ≥12 months
B5: Fixed Deposits | C5: Interest at slab rateTDS @10% if >₹40K/yr | D5: N/A | E5: 80TTB: ₹50K for senior citizens only | F5: 80TTB ₹50K* | G5: No deduction
B6: Bonds | C6: Interest: slab rate | D6: LTCG ≥12 months (listed) | E6: 54EC bonds: LTCG exempt up to ₹50L | F6: 54EC benefit | G6: No 54EC benefit
C7: LTCG 12.5%
C8: STCG: slab rate
B9: ULIP | C9: Tax-free maturity**Premium ≤₹2.5L/yr; else LTCG 10% | D9: Lock-in 5 years | E9: 80C up to ₹1.5L | F9: 80C + 10(10D) | G9: 10(10D) onlyNo 80C
E10: 10(10D) exemption on maturity
B11: NSC | C11: Interest: slab rateAccrued interest qualifies for 80C | D11: 5 years (lock-in) | E11: 80C up to ₹1.5L | F11: 80C benefit | G11: No 80C
B12: PPF | C12: EEE — fully tax-free | D12: 15 years (lock-in) | E12: 80C up to ₹1.5L | F12: 80C + EEE | G12: EEE retainedNo 80C deduction
E13: Interest u/s 10(11) exempt
B14: EPF | C14: EEE — fully tax-free | D14: 15 years (lock-in) | E14: 80C up to ₹1.5L | F14: 80C + EEE | G14: EEE retainedNo 80C deduction
E15: Interest u/s 10(11) exempt
B16: NPS | C16: 60% lump sum tax-free | D16: Till retirement (60 yrs) | E16: 80C ₹1.5L + 80CCD(1B) ₹50K | F16: 80C + extra ₹50K | G16: Only 80CCD(2)Employer contrib only
C17: 40% annuity: slab rate | E17: 80CCD(2) employer: both regimes
C20: For disinvstments, to spend/invest for goals : Go with following sequence
C21: Equity tagged as weak performer
C22: =B5
C23: =B6
C24: Equity tagged as neutral performer
C25: =B9
C26: =B11
C27: =B12
C28: =B14
C31: Selection of tax regime (Old regime vs new regime) for tax filing FY 25-26
C32: 1. Compute tax under both regimes and choose regime with lower tax burden
C33: 2. If total deductions are limited, the new regime is usually preferable.
C34: 3. Salaried taxpayers can have nil tax up to ₹12.75 lakh income under the new regime (subject to applicable conditions).
C35: 4. Old regime generally becomes beneficial when deductions exceed approximately ₹4–5 lakh through a combination of:
C36: Section 80C: ₹1.5 lakh
C37: Section 80CCD(1B) NPS: ₹0.5 lakh
C38: Section 80D: ₹25,000–₹75,000
C39: Home-loan interest: up to ₹2 lakh
C40: HRA exemption
C41: Other eligible deductions/exemptions
C44: Capital Gains Tax Planning Strategies
... C100: Evaluate tax efficiency of equity, debt, gold, REITs, InvITs, and real estate before investing.

Sheet Insurance Computation
B2: Computation of Life Innsurance Needs :
B4: Computation of Human Life Value (To replace the income) | J4: Steps in Insurance Planning
B5: Please enter value in the white cells: | G5: Excel Formula reference
J6: a. | K6: Identify insurance need
E7: Current annual Income of Insured | F7: =298000*12 | G7: Pmt | J7: •Income replacement needs
E8: Proposed Retirement Age | F8: 56 | J8: •Income protection needs
E9: Current Age | F9: 36 | J9: •Asset protection needs
E10: Years to Retirement | F10: =F8-F9 | G10: Nper | J10: b. | K10: Estimate the amount of insurance coverage required
E11: Interest rate per annum on investments | F11: 0.1 | J11: c. | K11: Estimate the tenure for which the insurance is required
E12: Expected Annual Inflation/Rate of income raise per annum | F12: 0.06 | J12: d. | K12: Identify the most suitable insurance product
E13: Discounting Rate | F13: =(1+F11)/(1+F12)-1 | G13: Rate | J13: e. | K13: Optimize the insurance premium
E14: Estimated Human Life Value | F14: =PV(F13,F10,-F7,0) | G14: PV | J14: f. | K14: Monitor the insurance coverage
B17: Computation of Insurance Cover based on analysis of Need (to Cover spouse's expense during her lifetime and obligations) | J17: STEPS FOR COMPUTING INSURANCE COVERAGE
B18: Please enter value in the white cells: | G18: Excel Formula reference | J18: STEP 1: KNOW YOUR FAMILY INCOME/EXPENSES
J19: STEP 2: KNOW YOUR FAMILY’S ONE-TIME NEEDS
E20: Current Mandatory Annual Expense of the family | F20: =SUM('3_Expenses '!I6:I24)*12 | G20: Pmt | J20: STEP 3: KNOW YOUR ASSETS BASE
E21: Life Expectancy of spouse (Dependent) | F21: 80 | J21: STEP 4: YOUR CALCULATION
E22: Current Age of Spouse | F22: 36
E23: Years to provide for | F23: =F21-F22 | G23: Nper | J23: Circumstances when you don’t need insurance
E24: Expected ROI p.a | F24: 0.1 | J24: 1. You don’t have dependants : If you are not married and nobody depends on your income, you don’t need life insurance.
E25: Inflation Rate p.a | F25: 0.06 | J25: 2. You have enough assets : If you have already built assets that can take care of your family in your absence, there’s no need to spend on life cover.
E26: Discounting Rate | F26: =(1+F24)/(1+F25)-1 | G26: Rate | J26: 3. Your spouse earns well : If your spouse has a good income and can sustain ..
E27: Corpus Needed to generate required income | F27: =PV(F26,F23,-F20,0) | G27: PV | J27: 4. You have retired : Insurance is meant to replace the income of an individual. So a retired person does not need cover, unless he has liabilities that extend into retirement
B30: Average of both methods | F30: =AVERAGE(E31:E32)
B31: Insurance Need to replace the income | E31: =F14 | J31: Five reasons you need to increase insurance cover
B32: Insurance Need to cover expenses | E32: =F27 | J32: 1. Your parents retire : Take additional insurance when your dependent parent(s) stop working or their income reduces due to any reason.
E33: Loans and Obligations Outstanding | F33: 2000000 | J33: 2. You get married : Even if your spouse works, he or she might be dependent on financial support from you. So increase your cover accordingly.
E34: Total Insurance Needed | F34: =F30+F33 | J34: 3. You become a parent ;Your responsibilities shoot up after the ..
J35: 4. You take a big loan : Your family will be in a spot if something happens to you and there’s not enough money to pay the EMIs. Take a cover equal to the loan amount.
E36: Insurance coverage already in place on life of the earning member | F36: 20000000 | J36: 5. You start a business : If you quit your job, you will need a bigger cover because you might have lost many of the benefits that employees are entitled to in the organised sector.
E37: Value of Assets Available for disposal | F37: =SUM('11. Inc Exp,Networth,Rec Invest'!I42)
E38: Additional Insurance Coverage Recommended | F38: =F34-F36-F37
B39: Conclusion : Rs 3.05 Crore is the additional term insurance value to be purchased
B42: Notes :
B43: In case employer provide insurance cover, the same can be reduced from insurance needs
B48: Computation of Health Insurance Coverage
B49: Rule of Thumb : Total health cover of family | K49: Note : Even if employer is providing health insurance cover, consider taking health insurance cover on your own, as employment may cease, post retirement coverage may cease or reduce
B50: Higher of
B51: A. 50% of Annual Gross Household Income | F51: Annual Gross Income | G51: ='2_Income'!I12*12 | K51: A. Medical Inflation is high and health is priority, hence health insurance is mandatory
B52: Or | F52: Health Insurance Coverage Needed | G52: =G51/2 | K52: Health is wealth, hence body need to be healthy in order to earn and support family . Self
...

Sheet 11. Inc Exp,Networth,Rec Invest
E2: Income and Expenses Summary - Monthly
B4: Income and Expenses | F4: Mr. M | G4: Mrs. M | H4: Others /Family | I4: Total | J4: Optional Remarks/Comments
E5: Total Income (NET) | F5: ='2_Income'!F30 | G5: ='2_Income'!G30 | H5: ='2_Income'!H30 | I5: ='2_Income'!I30
E7: Total Expenses | F7: ='3_Expenses '!F26 | G7: ='3_Expenses '!G26 | H7: ='3_Expenses '!H26 | I7: ='3_Expenses '!I26
E9: Savings I -II | I9: =I5-I7
E10: Savings ratio | I10: =I9/I5
E13: Investments (Ongoing) | F13: =SUM(F14:F18) | G13: =SUM(G14:G18) | H13: =SUM(H14:H18) | I13: =SUM(F13:H13)
E14: ='5_Recurring_Investments'!B2 | F14: ='5_Recurring_Investments'!C2 | I14: =SUM(F14:H14) | J14: Considered for Investment needs
E15: ='5_Recurring_Investments'!B3 | F15: ='5_Recurring_Investments'!C3 | I15: =SUM(F15:H15) | J15: Considered for Investment needs
E16: ='5_Recurring_Investments'!B4 | F16: ='5_Recurring_Investments'!C4 | I16: =SUM(F16:H16)
E17: ='5_Recurring_Investments'!B5 | F17: ='5_Recurring_Investments'!C5 | I17: =SUM(F17:H17)
E18: ='5_Recurring_Investments'!B6 | F18: ='5_Recurring_Investments'!C6 | I18: =SUM(F18:H18)
E19: ='5_Recurring_Investments'!B7 | F19: ='5_Recurring_Investments'!C7 | I19: =SUM(F19:H19) | J19: Considered for Investment needs
E20: ='5_Recurring_Investments'!B8
E22: Monthly surplus in hand III - IV | I22: =I9-I13
E23: EPF (Deduction by Employer) | F23: ='2_Income'!I18 | I23: =F23 | J23: Considered for Investment needs
E26: Computation of Netwoth :
E27: Assests / Investments : | I27: Current Value | K27: Long Term (Post Tax Earnings %)
D28: Finanical Assets | E28: Mutual Fund | I28: ='4A_Mutual_Funds'!H22 | K28: ='Assumptions & Computation'!E22
D29: Finanical Assets | E29: Equity | I29: ='4B_Equity_Stocks'!E24 | J29: Allocated for weak, neutral and strong | K29: =12%*0.875
D30: Finanical Assets | E30: FD | I30: ='4C_Fixed_Income'!E2 | J30: allocated | K30: =8%*0.7
D31: Finanical Assets | E31: Bonds | I31: ='4C_Fixed_Income'!E3 | J31: allocated | K31: =8%*0.7
D32: Finanical Assets | E32: NSC | I32: ='4C_Fixed_Income'!E4 | J32: allocated | K32: =6%*0.7
D33: Finanical Assets | E33: PPF | I33: ='4C_Fixed_Income'!E5 | J33: allocated | K33: =7%*0.7
D34: Finanical Assets | E34: EPF | I34: ='4C_Fixed_Income'!E6 | J34: allocated | K34: =8%*0.7
D35: Finanical Assets | E35: NPS | I35: ='4C_Fixed_Income'!E7 | J35: allocated | K35: =7%*0.7
D36: Finanical Assets | E36: Post Office Saving A/c | I36: ='4C_Fixed_Income'!E8 | J36: allocated | K36: =7%*0.7
D37: Finanical Assets | E37: Pls Specify 1 | K37: =7%*0.7
D38: Finanical Assets | E38: Pls Specify 1 | K38: =7%*0.7
D39: Finanical Assets | E39: Pls Specify 1 | K39: =7%*0.7
D40: Finanical Assets | E40: Liquid Assets | I40: ='6_Liquid_Capital'!C10 | J40: allocated | K40: =6%*0.7
D41: Finanical Assets | E41: Liquid Assets | I41: ='6_Liquid_Capital'!C11 | K41: =6%*0.7
D42: Finanical Assets | I42: =SUM(I28:I41) | K42: =SUMPRODUCT(I28:I41,K28:K41)/I42
D44: Non Financial Assets | E44: Real Estate | I44: ='4D_Real_Estate'!C10 | K44: =8%*0.875 | L44: Long term Appreciation Rate
D45: Non Financial Assets | E45: Gold & Others | I45: ='4E_Gold & Others'!C10 | K45: =8%*0.875
D46: Non Financial Assets | E46: Pls Specify 1 | K46: =8%*0.875
D47: Non Financial Assets | I47: =SUM(I44:I46) | K47: =SUMPRODUCT(I44:I46,K44:K46)/I47
E49: Total Assets / Investments | I49: =SUM(I42,I47)
E51: Total Loans | I51: ='8_Loans_Liabilities'!C10
E53: Net Worth | I53: =I49-I51
...

Sheet Retirement Plan
B2: Retirement corpus needed considering providing for his wife's lifetime also
B4: 1) What is the corpus requirement to ensure that he is able to sustain the same standard of living for 15 years after retirement?
B5: Computation
B6: Particulars | C6: Input/Computation | D6: Metric | E6: Amount (Rs.) | F6: Calculation
B7: Current Age of Mr M | C7: Input | D7: Years | E7: ='1_Personal_Details'!D5
B8: Retirement Age | C8: Input | D8: Years | E8: ='1_Personal_Details'!H5
B9: Current Age of Mrs M (Housewife) | C9: Input | D9: Years | E9: ='1_Personal_Details'!D6
B10: Time to Retire | C10: Computation | D10: Years | E10: =E8-E7
B12: Life Expectancy of Mr M | C12: Input | D12: Years | E12: ='Assumptions & Computation'!E43
B13: Life Expectancy of Mrs. M | C13: Input | D13: Years | E13: ='Assumptions & Computation'!E44
B14: Age of Mrs M at the time of retirement of Mr M | C14: Computation | D14: Years | E14: =E8-(E7-E9)
B15: No. of Years to be served Post Retirement of Mr M | C15: Computation | D15: Years | E15: =E13-E14
B17: Annual Living expenses (at current age) | C17: Input | D17: INR | E17: =SUM('3_Expenses '!I6:I21)*12
B18: Estimated Living Expenses at the time of retirement | C18: Input | D18: INR | E18: =(SUM('3_Expenses '!I6:I20)-'3_Expenses '!I8)*12 | F18: Exclude school fees etc and add additional medical spend etc
B19: Current Inflation (given) | C19: Asssumed | D19: % | E19: ='Assumptions & Computation'!D3
B20: Living expense (at retirement of Mr M.) | C20: Computation | D20: INR | E20: =FV(E19,E10,,-E18)
B22: Expected return on investment | C22: Asssumed | D22: % | E22: ='Assumptions & Computation'!E23
B23: Expected Inflation post retirement | C23: Asssumed | D23: % | E23: ='Assumptions & Computation'!D3
B24: Inflation adjusted return (During Retirement years) | C24: Asssumed | D24: % | E24: =((1+E22)/(1+E23))-1
B25: Retirement corpus required at the time of retirement | E25: =PV(E24,E15,-E20,0,1) | F25: 1 denotes payment at the beginning of the period - as money need to be generated at the beginning of period for spend
B26: One Time Spend Post Retirement | C26: Input | E26: ='10_Financial_Goals'!E20
B27: Time for above spend | C27: Check Period | D27: Years | E27: ='10_Financial_Goals'!D20
B28: Current Inflation (given) | C28: Asssumed | D28: % | E28: =E19
B29: Value on the date of retirement | E29: =FV(E28,E27,,-E26)
B30: Total Retirement Corpus Needed for Retirement spend and one time goal post retirment | E30: =E25+E29
B34: 2. Computation of additional investments to be done to meet shortfall of Corpus | C34: Recurring Spend Plan | D34: One Time Spend Plan | E34: Total SIP Needs
B35: 2. In this case Corpus needed for retirement | C35: =E25 | D35: =E29
B36: Projected Corpus based on his current value of investments | C36: ='10_Financial_Goals'!Y21 | D36: 0
B37: Shortfall in corpus | C37: =C35-C36 | D37: =D35-D36
B39: Years to retire | C39: ='10_Financial_Goals'!D19 | D39: ='10_Financial_Goals'!D20
B40: Expected return on investment (Post Tax) | C40: ='Assumptions & Computation'!E22 | D40: ='Assumptions & Computation'!E22
B41: Additional monthly investments to be done | C41: =PMT(C40/12,C39*12,0,-C37) | D41: =PMT(D40/12,D39*12,0,-D37) | E41: =SUM(C41:D41) | F41: This has one goal due in 20 years and other goal due in 24 years
B43: Less SIPs ongoing | E43: =SUM('11. Inc Exp,Networth,Rec Invest'!I15,'11. Inc Exp,Networth,Rec Invest'!I16,'11. Inc Exp,Networth,Rec Invest'!I19,'11. Inc Exp,Networth,Rec Invest'!I23)
B44: Additional SIPs needed to reach goals | E44: =E41-E43
B47: Stepping up investments
B48: Stepping up of investments each year can help to start SIP with lower value. Also it helps to reach corpus creation at faster manner
A50: Increase p.a | B50: 3. Total Retirement Corpus Calculation (If Step up investments are considered)
B51: Suppose client has limitation on annual contribution, then we need to model how much step up can help him reach his goals | F51: 0.1
C52: Years to retire | D52: Age of Mr. M | E52: Annual Retirement Contribution | F52: Step up increase in Annual Contribution | G52: Total Annual Contribution | H52: Current Corpus (Allocated for retirement) | I52: Rate p.a. | J52: Future Value at age 60 | K52: Cumulative FV
B53: One Time corpus to FV on date of Retirement | C53: ='1_Personal_Details'!H5-'1_Personal_Details'!D5 | D53: ='1_Personal_Details'!D5 | H53: ='10_Financial_Goals'!X19 | I53: ='Assumptions & Computation'!E22 | J53: =FV(I53,C53,,-H53) | K53: =J53
...

Sheet 10_Financial_Goals
J1: Cash Flow arrangements : After allocating Assets to respective Goals | X1: Total
A2: Goal | B2: Importance (Essential / Desirable) | C2: Target Year | D2: Years to go | E2: Today’s Cost | F2: Nature Of Spend (One Time Or Annual) | G2: Inflation Assumed | H2: Future Value Needed | I2: Optional Remarks /Comments | J2: Asset | K2: Current Value (INR) | L2: Asset | M2: Current Value (INR) | N2: Asset | O2: Current Value (INR) | P2: Asset | Q2: Current Value (INR) | R2: Asset | S2: Current Value (INR) | T2: Asset | U2: Current Value (INR) | V2: Asset | W2: Current Value (INR) | X2: Total Current Value of Asset Allocated | Y2: Gap on today's value | Z2: FV of needs (unallocated assets) | AA2: ROI (Post Tax) on planned EMIs | AB2: Monthly Investments Needed | AC2: Monthly investments already happening | AD2: Remaining Monthly investments needed | AE2: Investment Mode
A3: Car Purchase | G3: ='Assumptions & Computation'!D3 | H3: =FV(G3,D3,,-E3) | K3: ='4B_Equity_Stocks'!E26 | M3: =839368 | X3: =K3+M3+O3+Q3+S3+U3+W3 | Y3: =E3-X3 | Z3: =FV(G3,D3,,-Y3) | AB3: =IFERROR(PMT(AA3/12,D3*12,,-Z3),0) | AD3: =AB3-AC3
A4: Foreign Travel | G4: ='Assumptions & Computation'!D3 | H4: =FV(G4,D4,,-E4) | M4: ='11. Inc Exp,Networth,Rec Invest'!I30-'10_Financial_Goals'!M3 | O4: ='4C_Fixed_Income'!E3 | X4: =K4+M4+O4+Q4+S4+U4+W4 | Y4: =E4-X4 | Z4: =FV(G4,D4,,-Y4) | AB4: =IFERROR(PMT(AA4/12,D4*12,,-Z4),0) | AD4: =AB4-AC4
A5: House Purchase | G5: ='Assumptions & Computation'!D8 | H5: =FV(G5,D5,,-E5) | Q5: ='4B_Equity_Stocks'!E27-Q4 | S5: ='4C_Fixed_Income'!E4 | U5: ='4C_Fixed_Income'!E5 | X5: =K5+M5+O5+Q5+S5+U5+W5 | Y5: =E5-X5 | Z5: =FV(G5,D5,,-Y5) | AA5: ='Assumptions & Computation'!E22 | AB5: =IFERROR(PMT(AA5/12,D5*12,,-Z5),0) | AD5: =AB5-AC5
A6: Child 1 Education | G6: ='Assumptions & Computation'!D4 | H6: =FV(G6,D6,,-E6) | U6: ='11. Inc Exp,Networth,Rec Invest'!I34 | X6: =K6+M6+O6+Q6+S6+U6+W6 | Y6: =E6-X6 | Z6: =FV(G6,D6,,-Y6) | AA6: ='Assumptions & Computation'!E22 | AB6: =IFERROR(PMT(AA6/12,D6*12,,-Z6),0) | AD6: =AB6-AC6
A7: Child 2 Education | G7: ='Assumptions & Computation'!D4 | H7: =FV(G7,D7,,-E7) | U7: ='4B_Equity_Stocks'!E28 | W7: ='11. Inc Exp,Networth,Rec Invest'!I28 | X7: =K7+M7+O7+Q7+S7+U7+W7 | Y7: =E7-X7 | Z7: =FV(G7,D7,,-Y7) | AA7: ='Assumptions & Computation'!E22 | AB7: =IFERROR(PMT(AA7/12,D7*12,,-Z7),0) | AD7: =AB7-AC7
A8: Child 1 Marriage | G8: ='Assumptions & Computation'!D3 | H8: =FV(G8,D8,,-E8) | X8: =K8+M8+O8+Q8+S8+U8+W8 | Y8: =E8-X8 | Z8: =FV(G8,D8,,-Y8) | AA8: ='Assumptions & Computation'!E22 | AB8: =IFERROR(PMT(AA8/12,D8*12,,-Z8),0) | AC8: ='11. Inc Exp,Networth,Rec Invest'!I14 | AD8: =AB8-AC8
A9: Child 2 Marriage | G9: ='Assumptions & Computation'!D3 | H9: =FV(G9,D9,,-E9) | X9: =K9+M9+O9+Q9+S9+U9+W9 | Y9: =E9-X9 | Z9: =FV(G9,D9,,-Y9) | AA9: ='Assumptions & Computation'!E22 | AB9: =IFERROR(PMT(AA9/12,D9*12,,-Z9),0) | AD9: =AB9-AC9
A10: House Purchase 2 | E10: =15000000*0 | G10: ='Assumptions & Computation'!D8 | H10: =FV(G10,D10,,-E10) | X10: =K10+M10+O10+Q10+S10+U10+W10 | Y10: =E10-X10 | Z10: =FV(G10,D10,,-Y10) | AA10: ='Assumptions & Computation'!E22 | AB10: =IFERROR(PMT(AA10/12,D10*12,,-Z10),0) | AD10: =AB10-AC10
A11: Loan Repayment | X11: =K11+M11+O11+Q11+S11+U11+W11 | Y11: =E11-X11 | Z11: =FV(G11,D11,,-Y11) | AA11: ='Assumptions & Computation'!E22 | AB11: =IFERROR(PMT(AA11/12,D11*12,,-Z11),0) | AD11: =AB11-AC11
A12: Social Commitments | X12: =K12+M12+O12+Q12+S12+U12+W12 | Y12: =E12-X12 | Z12: =FV(G12,D12,,-Y12) | AA12: ='Assumptions & Computation'!E22 | AB12: =IFERROR(PMT(AA12/12,D12*12,,-Z12),0) | AD12: =AB12-AC12
E13: =SUMIF(F3:F12,F13,E3:E12) | X13: =K13+M13+O13+Q13+S13+U13+W13 | Y13: =E8-X13 | Z13: =FV(G8,D8,,-Y13) | AB13: =IFERROR(PMT(AA13/12,D13*12,,-Z13),0) | AD13: =AB13-AC13
E14: =SUMIF(F3:F12,F14,E3:E12) | K14: =SUM(K3:K12) | M14: =SUM(M3:M12) | N14: =SUM(N2:N7) | O14: =SUM(O3:O12) | P14: =SUM(P2:P7) | Q14: =SUM(Q3:Q12) | R14: =SUM(R2:R7) | S14: =SUM(S3:S12) | T14: =SUM(T2:T7) | U14: =SUM(U3:U12) | W14: =SUM(W3:W12) | X14: =SUM(X3:X12) | Y14: =SUM(Y3:Y12) | Z14: =SUM(Z3:Z12) | AB14: =SUM(AB3:AB12) | AC14: =SUM(AC3:AC12) | AD14: =SUM(AD3:AD12)
Q15: ='4B_Equity_Stocks'!E27
K16: ='4B_Equity_Stocks'!E26-'10_Financial_Goals'!K14 | M16: ='4C_Fixed_Income'!E2-'10_Financial_Goals'!M14 | O16: ='4C_Fixed_Income'!E3-O14 | Q16: ='4B_Equity_Stocks'!E27-'10_Financial_Goals'!Q14 | S16: ='4C_Fixed_Income'!E4-'10_Financial_Goals'!S14 | U16: ='4C_Fixed_Income'!E5-'10_Financial_Goals'!U14 | W16: ='4C_Fixed_Income'!E6-W14
A18: POST RETIREMENT REGULAR AND ONE TIME SPEND
A19: Retirement Cost | H19: ='Retirement Plan'!E25 | I19: ='Assumptions & Computation'!E26 | J19: ='11. Inc Exp,Networth,Rec Invest'!E35 | K19: ='11. Inc Exp,Networth,Rec Invest'!I35 | M19: ='11. Inc Exp,Networth,Rec Invest'!I36 | N19: ='11. Inc Exp,Networth,Rec Invest'!E40 | O19: ='11. Inc Exp,Networth,Rec Invest'!I40 | X19: =K19+M19+O19+Q19+S19+U19+W19 | Y19: =FV(I19,D19,,-X19) | Z19: =H19-Y19 | AA19: ='Assumptions & Computation'!E22 | AB19: =PMT(AA19/12,D19*12,,-Z19) | AC19: =SUM('11. Inc Exp,Networth,Rec Invest'!I15,'11. Inc Exp,Networth,Rec Invest'!I16,'11. Inc Exp,Networth,Rec Invest'!I19,'11. Inc Exp,Networth,Rec Invest'!I23) | AD19: =AB19-AC19
A20: Orphanage | H20: ='Retirement Plan'!E29 | I20: ='Assumptions & Computation'!E26 | X20: =K20+M20+O20+Q20+S20+U20+W20 | Y20: =FV(I20,D20,,-X20) | Z20: =H20-Y20 | AA20: ='Assumptions & Computation'!E22 | AB20: =PMT(AA20/12,D20*12,,-Z20) | AC20: =SUM('11. Inc Exp,Networth,Rec Invest'!I16,'11. Inc Exp,Networth,Rec Invest'!I17,'11. Inc Exp,Networth,Rec Invest'!I20,'11. Inc Exp,Networth,Rec Invest'!I24) | AD20: =AB20-AC20
H21: =SUM(H19:H20) | X21: =SUM(X19:X20) | Y21: =SUM(Y19:Y20) | Z21: =SUM(Z19:Z20) | AB21: =SUM(AB19:AB20) | AC21: =SUM(AC19:AC20) | AD21: =SUM(AD19:AD20)
A22: Total EMIs needed for future goals | AD22: =SUM(AD14,AD21)
A24: Do you wish to dispose any of the asset during retirement | X24: =X14+X19
A25: Do you wish to gift any of the asset during retirement | X25: ='11. Inc Exp,Networth,Rec Invest'!I42
X26: =X25-X24
A27: Tag Needs / Goals
A28: Map needs / Goals as Essential/Desirable
X30: ='11. Inc Exp,Networth,Rec Invest'!I44
A31: Chronlogically of Financial Needs to be sorted
A33: Asset Allocation Rule for respective goals
A34: Weal Tagged Stocks
A35: Weak tagged MFs
A36: Fixed Deposits
A37: Bonds
A38: Neutral Tagged Stocks
A39: Neutral tagged MFs
A40: ULIPs etc
A41: NSC
A42: PPF
A43: Any Real Estate for sale etc
... A61: If asset allocation value is more than financial needs , do not allocate more than financial needs

Sheet 1_Personal_Details
A1: Questions | B1: Details to be filled by Client
A4: Family Details
A5: Client Name | D5: =(D$3-C5)/365.25 | E5: =IF(H5>0,(ROUND($E$2+(H5-D5),0)),"NA")
A6: Spouse Name | D6: =(D$3-C6)/365.25 | E6: =IF(H6>0,(ROUND($E$2+(H6-D6),0)),"NA")
A7: Child 1 Name | D7: =(D$3-C7)/365.25 | E7: =IF(H7>0,(ROUND($E$2+(H7-D7),0)),"NA")
A8: Child 2 Name | D8: =(D$3-C8)/365.25 | E8: =IF(H8>0,(ROUND($E$2+(H8-D8),0)),"NA")
A9: Child 3 Name | E9: =IF(H9>0,(ROUND($E$2+(H9-D9),0)),"NA")
A10: Father
A11: Mother | D11: =(D$3-C11)/365.25
A12: Other Dependents 1
A13: Other Dependents 2

Sheet 2_Income
I6: =SUM(F6:H6)
D7: =D6+1 | I7: =SUM(F7:H7)
D8: =D7+1 | H8: ='4D_Real_Estate'!E10 | I8: =SUM(F8:H8)
D9: =D8+1 | I9: =SUM(F9:H9)
D10: =D9+1 | I10: =SUM(F10:H10)
D11: =D10+1 | I11: =SUM(F11:H11)
F12: =SUM(F6:F11) | G12: =SUM(G6:G11) | H12: =SUM(H6:H11) | I12: =SUM(I6:I11)
I17: =SUM(F17:H17)
D18: =+D17+1 | I18: =SUM(F18:H18)
F24: =F6-F17-F18 | G24: =G6-G17-G18 | H24: =H6-H17-H18 | I24: =SUM(F24:H24)
D25: =D24+1 | F25: =F7 | G25: =G7 | H25: =H7 | I25: =SUM(F25:H25)
D26: =D25+1 | F26: =F8 | G26: =G8 | H26: =H8 | I26: =SUM(F26:H26)
D27: =D26+1 | F27: =F9 | G27: =G9 | H27: =H9 | I27: =SUM(F27:H27)
D28: =D27+1 | F28: =F10 | G28: =G10 | H28: =H10 | I28: =SUM(F28:H28)
D29: =D28+1 | F29: =F11 | G29: =G11 | H29: =H11 | I29: =SUM(F29:H29)
F30: =SUM(F24:F29) | G30: =SUM(G24:G29) | H30: =SUM(H24:H29) | I30: =SUM(I24:I29)

Sheet 3_Expenses 
I5: =SUM(F5:H5)
I6: =SUM(F6:H6)
D7: =D6+1 | I7: =SUM(F7:H7)
D8: =D7+1 | I8: =SUM(F8:H8)
D9: =D8+1 | I9: =SUM(F9:H9)
D10: =D9+1 | I10: =SUM(F10:H10)
D11: =D10+1 | I11: =SUM(F11:H11)
D12: =D11+1 | I12: =SUM(F12:H12)
D13: =D12+1 | I13: =SUM(F13:H13)
D14: =D13+1 | I14: =SUM(F14:H14)
D15: =D14+1 | I15: =SUM(F15:H15)
D16: =D15+1 | I16: =SUM(F16:H16)
I19: =SUM(F19:H19)
I20: =SUM(F20:H20)
I23: =SUM(F23:H23)
D24: =D23+1 | I24: =SUM(F24:H24)
D25: =D24+1 | I25: =SUM(F25:H25)
F26: =SUM(F5:F21) | G26: =SUM(G5:G21) | H26: =SUM(H5:H25) | I26: =SUM(I5:I25)

Sheet 7_Emergency_Fund
B1: Question | C1: Answer | D1: Optional Remarks /Comments
B2: Emergency fund available? (Yes/No) | C2: yes
D3: =D5*6
C5: ='3_Expenses '!I26 | D5: =G22
C6: =C3/C5
D10: ='3_Expenses '!E6 | G10: ='3_Expenses '!H6
D11: ='3_Expenses '!E7 | G11: ='3_Expenses '!H7
D12: ='3_Expenses '!E8 | G12: ='3_Expenses '!H8
D13: ='3_Expenses '!E9 | G13: ='3_Expenses '!H9
D14: ='3_Expenses '!E10 | G14: ='3_Expenses '!H10
D15: ='3_Expenses '!E11 | G15: ='3_Expenses '!H11
D17: ='3_Expenses '!E13 | G17: ='3_Expenses '!H13
D18: ='3_Expenses '!E14 | G18: ='3_Expenses '!H14
D19: ='3_Expenses '!E15 | G19: ='3_Expenses '!H15
D20: ='3_Expenses '!E23 | G20: ='3_Expenses '!H23
D21: ='3_Expenses '!E24 | G21: ='3_Expenses '!H24
G22: =SUM(G10:G21)
C32: ='11. Inc Exp,Networth,Rec Invest'!I10

Sheet 4A_Mutual_Funds
B1: Fund Name & Scheme | C1: Type (Direct Or Regular) | D1: Folio | E1: No Of Units | F1: Purchase Price | G1: Current NAV | H1: Current Value | I1: SIP Amount | J1: SIP Frequency (Monthly/Weekly etc) | K1: Optional Remarks /Comments
B2: - MIRAE ASSET MIDCAP FUND - REGULAR PLAN | J2: Monthly | K2: NA
H22: =SUM(H2:H21) | I22: =SUM(I2:I21)

Sheet 4B_Equity_Stocks
B1: Stock Name | C1: Stock ISIN | D1: Quantity | E1: Current Price | F1: Current Value | G1: Purchase Cost Rate | H1: Long Term / Trading | I1: Optional Remarks /Comments
B2: Ashok Leyland | F2: Neutral
E24: =SUM(E2:E23)
E26: =SUMIF(F$2:F$23,F26,E$2:E$23)
E27: =SUMIF(F$2:F$23,F27,E$2:E$23)
E28: =SUMIF(F$2:F$23,F28,E$2:E$23)
E29: =SUM(E26:E28)
E30: =E24-E29

Sheet 4C_Fixed_Income
B1: Instrument | C1: Details of Instrument | D1: Invested Amount (Not Mandatory) | E1: Current Value | F1: Maturity Date | G1: Optional Remarks /Comments
B2: FD | C2: State Bank FD
E3: =D3*109%
E4: =D4*1.5
E8: =400000/2
D10: =SUM(D2:D9) | E10: =SUM(E2:E9)

Sheet 5_Recurring_Investments
B1: Investment Type | C1: Monthly Amount | D1: Optional Remarks /Comments
B2: Mutual Fund SIP | C2: ='4A_Mutual_Funds'!I22 | D2: For House Purchase
C10: =SUM(C2:C7)

Sheet 4D_Real_Estate
B1: Property Type | C1: Current Market Value | D1: Loan Outstanding | E1: Rental Income | F1: Optional Remarks /Comments
B2: Residential 4 story building
C10: =SUM(C2:C9) | D10: =SUM(D2:D9) | E10: =SUM(E2:E9)

Sheet 4E_Gold & Others
B1: Asset | C1: Current Value | D1: Optional Remarks /Comments
B2: 100 grams gold jewellery on my name
C10: =SUM(C2:C9)

Sheet 6_Liquid_Capital
B1: Category | C1: Amount | D1: Optional Remarks /Comments
B2: Savings Account Bank Balance | D2: planning to reserve 2 lacs for emergency fund
C10: =SUM(C2:C9)

Sheet 8_Loans_Liabilities
B1: Loan Type | C1: Outstanding Amount | D1: EMI | E1: Interest Rate | F1: Tenure Left | G1: Optional Remarks /Comments
B2: Home Loan | C2: ='4D_Real_Estate'!D3 | F2: 5 years left | G2: EMI due until Mar 2031
C10: =SUM(C2:C9)

Sheet 9_Insurance_Details
B1: Policy Type | C1: Type | D1: Company | E1: Cover Amount | F1: Annual Premium | G1: Year of Maturity | H1: Optional Remarks /Comments
B2: Term Plan | C2: Life | D2: HDFC | H2: Age of client on maturity will be 60

Sheet Retirement Plan-Case Study-NA
B2: Case 1
A3: Scenario 1 | B3: Mr. Z, aged 52 years, is working in a leading company. His net savings are Rs. 50,000 p.m. Based on salary growth and other factors, he expects this to rise by 20% p.a. till his retirement at age 60. This does not include monthly contributions of Rs. 9,000 (Rs.4000 own contribution; Rs.5000 employer contribution) to various funds towards retirement corpus. These are expected to grow by 20% p.a. till retirement. The retirement corpus by the end of the year will be Rs. 12 lakhs, entirely in debt, which will yield 8 % p.a. on average. Besides his own residential house and the retirement corpus, his savings and investments will amount to Rs.50 lakhs by the end of the year, 30% of which will be in equity.
B4: His current expenses are Rs. 40,000 per month.
A5: Scenario 2 | B5: Assuming his wife's current Age is 48 and her life expectancy is 85, what will be the retirement corpus needed by him
B9: 1) What is the corpus requirement to ensure that he is able to sustain the same standard of living for 15 years after retirement?
B10: Computation
B11: Particulars | C11: Input/Computation | D11: Metric | E11: Amount (Rs.) | F11: Calculation
B12: Current Age | C12: Input | D12: Years | E12: 52
B13: Retirement Age | C13: Input | D13: Years | E13: 60
B14: Time to Retire | C14: Computation | D14: Years | E14: =E13-E12
B16: Life Expectancy | C16: Input | D16: Years | E16: 75
B17: No. of Years Post Retirement | C17: Computation | D17: Years | E17: =E16-E13
B19: Annual Living expenses (at current age) | C19: Input | D19: INR | E19: 480000 | F19: Expenses @ Rs.40,000 per month
B20: Current Inflation (given) | C20: Asssumed | D20: % | E20: ='Assumptions & Computation'!D3
B21: Living expense (at retirement) | C21: Computation | D21: INR | E21: =FV(E20,E14,,-480000)
B23: Expected return on investment | C23: Asssumed | D23: % | E23: ='Assumptions & Computation'!E22
B24: Expected Inflation post retirement | C24: Asssumed | D24: % | E24: ='Assumptions & Computation'!D3
B25: Inflation adjusted return (During Retirement years) | C25: Asssumed | D25: % | E25: =((1+E23)/(1+E24))-1
B26: Retirement corpus required | E26: =PV(E25,E17,-E21,0,1) | F26: 1 denotes payment at the beginning of the period - as money need to be generated at the beginning of period for spend
B29: 2. Total Retirement Corpus Calculation (Based on current investment pattern)
B30: Years to
B31: Retirement | C31: 8 | D31: 7 | E31: 6 | F31: 5 | G31: 4 | H31: 3 | I31: 2 | J31: 1 | K31: 0
B32: Age of Mr. Z | C32: 52 | D32: 53 | E32: 54 | F32: 55 | G32: 56 | H32: 57 | I32: 58 | J32: 59 | K32: 60
B33: Annual Retirement Contribution | D33: =9000*12*1.2 | E33: =D33*1.2 | F33: =E33*1.2 | G33: =F33*1.2 | H33: =G33*1.2 | I33: =H33*1.2 | J33: =I33*1.2 | K33: =J33*1.2
B34: Corpus (at age 52) | C34: 1200000
B35: Rate p.a. | C35: 0.08
B36: Future Value at age 60 | C36: =FV($C$35,C31,,-C34) | D36: =FV($C$35,D31,,-D33) | E36: =FV($C$35,E31,,-E33) | F36: =FV($C$35,F31,,-F33) | G36: =FV($C$35,G31,,-G33) | H36: =FV($C$35,H31,,-H33) | I36: =FV($C$35,I31,,-I33) | J36: =FV($C$35,J31,,-J33) | K36: =FV($C$35,K31,,-K33)
B37: Total Corpus at Retirement (Summation of all future values) | J37: =SUM(C36:K36)
B38: @[Rs. 9000 p.m. with Growth @ 20% p.a.]
B39: *[=FV(8%,Year to Retirement,,-Contribution towards retirement corpus)]
B41: Computation of additional investments to be done to meet shortfall of Corpus
B42: 3. In this case Corpus needed for retirement | C42: =E26
B43: Projected Corpus based on his current investments plan | C43: =J37
B44: Shortfall in corpus | C44: =C42-C43
B46: Years to retire | C46: =E14
B47: Expected return on investment (Post Tax) | C47: ='Assumptions & Computation'!E22
B48: Additional monthly investments to be done | C48: =PMT(C47/12,C46*12,0,-C44)
A52: Scenario 2 | B52: Assuming his wife's current Age is 48 and her life expectancy is 85, what will be the retirement corpus needed by him
B54: 1) What is the corpus requirement to ensure that he is able to sustain the same standard of living for 15 years after retirement?
B55: Computation
...

Sheet Asset Returns
B2: Ranking Of Assets, based on safety, liquidity, Returns, Divisibility - For Academic Purpose only
B3: SL No | C3: Asset Class | D3: Safety | E3: Liquidity | F3: Post Tax Returns | G3: Divisibility | H3: Period of Holding | I3: Suitable for
B4: 1 | C4: FD | D4: 5 | E4: 2 | F4: 2 | G4: 2 | H4: Long | I4: Assured Return
B5: 2 | C5: Bonds | D5: 4 | E5: 2 | F5: 2 | G5: 3 | H5: Long | I5: Assured Return
B6: 3 | C6: PPF | D6: 5 | E6: 1 | F6: 3 | G6: 1 | H6: Very Long | I6: Assured Return
B7: 4 | C7: NPS (Hybrid) | D7: 4 | E7: 1 | F7: 4 | G7: 1 | H7: Very Long | I7: Retirement Planning
B8: 5 | C8: Preference Shares | D8: 3 | E8: 2 | F8: 3 | G8: 3 | H8: Long | I8: Assured Return
B9: 6 | C9: Equity | D9: 2 | E9: 4 | F9: 4 | G9: 5 | H9: Long | I9: Wealth Building
B10: 7 | C10: Mutual Fund (Eq) | D10: 3 | E10: 4 | F10: 4 | G10: 5 | H10: Long | I10: Wealth Building
B11: 8 | C11: Real Estate | D11: 5 | E11: 1 | F11: 4 | G11: 1 | H11: Very Long | I11: Wealth Building
B12: 9 | C12: Gold | D12: 5 | E12: 4 | F12: 3 | G12: 2 | H12: Long | I12: Wealth Building
B13: 10 | C13: Crypto | D13: 1 | E13: 4 | F13: Highly Volatile | G13: 4 | H13: Short | I13: High Returns
B14: 11 | C14: REITs | D14: 3 | E14: 3 | F14: 3 | G14: 4 | H14: Long | I14: High Returns
B15: 12 | C15: PMS | D15: 3 | E15: 3 | F15: 4 | G15: 3 | H15: Long | I15: Wealth Building
B16: 13 | C16: Private Equity | D16: 2 | E16: 1 | F16: Very high | G16: 1 | H16: Long | I16: Very High Returns
B17: 14 | C17: Venture Capital | D17: 1 | E17: 1 | F17: Extremely high | G17: 1 | H17: Long | I17: Extremely High Returns
B20: for Academic Purpose - Move to last

Sheet Risk Questannaire
C2: Risk Questannaire Link
